{
  "configurations": {
    "CVE_data_version": "4.0",
    "nodes": [
      {
        "cpe_match": [
          {
            "cpe23Uri": "cpe:2.3:a:python:python:*:*:*:*:*:*:*:*",
            "versionEndIncluding": "3.6.4",
            "vulnerable": true
          }
        ],
        "operator": "OR"
      }
    ]
  },
  "cve": {
    "CVE_data_meta": {
      "ASSIGNER": "cve@mitre.org",
      "ID": "CVE-2017-18207"
    },
    "affects": {
      "vendor": {
        "vendor_data": [
          {
            "product": {
              "product_data": [
                {
                  "product_name": "python",
                  "version": {
                    "version_data": [
                      {
                        "version_affected": "\u003c=",
                        "version_value": "3.6.4"
                      }
                    ]
                  }
                }
              ]
            },
            "vendor_name": "python"
          }
        ]
      }
    },
    "data_format": "MITRE",
    "data_type": "CVE",
    "data_version": "4.0",
    "description": {
      "description_data": [
        {
          "lang": "en",
          "value": "** DISPUTED ** The Wave_read._read_fmt_chunk function in Lib/wave.py in Python through 3.6.4 does not ensure a nonzero channel value, which allows attackers to cause a denial of service (divide-by-zero and exception) via a crafted wav format audio file. NOTE: the vendor disputes this issue because Python applications \"need to be prepared to handle a wide variety of exceptions.\""
        }
      ]
    },
    "problemtype": {
      "problemtype_data": [
        {
          "description": [
            {
              "lang": "en",
              "value": "CWE-369"
            }
          ]
        }
      ]
    },
    "references": {
      "reference_data": [
        {
          "name": "https://bugs.python.org/issue32056",
          "refsource": "MISC",
          "tags": [
            "Issue Tracking",
            "Vendor Advisory"
          ],
          "url": "https://bugs.python.org/issue32056"
        }
      ]
    }
  },
  "impact": {
    "baseMetricV2": {
      "cvssV2": {
        "accessComplexity": "MEDIUM",
        "accessVector": "NETWORK",
        "authentication": "NONE",
        "availabilityImpact": "PARTIAL",
        "baseScore": 4.3,
        "confidentialityImpact": "NONE",
        "integrityImpact": "NONE",
        "vectorString": "AV:N/AC:M/Au:N/C:N/I:N/A:P",
        "version": "2.0"
      },
      "exploitabilityScore": 8.6,
      "impactScore": 2.9,
      "obtainAllPrivilege": false,
      "obtainOtherPrivilege": false,
      "obtainUserPrivilege": false,
      "severity": "MEDIUM",
      "userInteractionRequired": true
    },
    "baseMetricV3": {
      "cvssV3": {
        "attackComplexity": "LOW",
        "attackVector": "NETWORK",
        "availabilityImpact": "HIGH",
        "baseScore": 6.5,
        "baseSeverity": "MEDIUM",
        "confidentialityImpact": "NONE",
        "integrityImpact": "NONE",
        "privilegesRequired": "NONE",
        "scope": "UNCHANGED",
        "userInteraction": "REQUIRED",
        "vectorString": "CVSS:3.0/AV:N/AC:L/PR:N/UI:R/S:U/C:N/I:N/A:H",
        "version": "3.0"
      },
      "exploitabilityScore": 2.8,
      "impactScore": 3.6
    }
  },
  "lastModifiedDate": "2018-03-23T15:57Z",
  "publishedDate": "2018-03-01T05:29Z"
}